Traceback (most recent call last):
  File "/home/zaurall/projects/pmldl-mlops/.venv/lib/python3.11/site-packages/lockfile/pidlockfile.py", line 77, in acquire
    write_pid_to_pidfile(self.path)
  File "/home/zaurall/projects/pmldl-mlops/.venv/lib/python3.11/site-packages/lockfile/pidlockfile.py", line 161, in write_pid_to_pidfile
    pidfile_fd = os.open(pidfile_path, open_flags, open_mode)
                 ^^^^^^^^^^^^^^^^^^^^^^^^^^^^^^^^^^^^^^^^^^^^
FileExistsError: [Errno 17] File exists: '/home/zaurall/projects/pmldl-mlops/services/airflow/airflow-triggerer.pid'

During handling of the above exception, another exception occurred:

Traceback (most recent call last):
  File "/home/zaurall/projects/pmldl-mlops/.venv/bin/airflow", line 8, in <module>
    sys.exit(main())
             ^^^^^^
  File "/home/zaurall/projects/pmldl-mlops/.venv/lib/python3.11/site-packages/airflow/__main__.py", line 57, in main
    args.func(args)
  File "/home/zaurall/projects/pmldl-mlops/.venv/lib/python3.11/site-packages/airflow/cli/cli_config.py", line 49, in command
    return func(*args, **kwargs)
           ^^^^^^^^^^^^^^^^^^^^^
  File "/home/zaurall/projects/pmldl-mlops/.venv/lib/python3.11/site-packages/airflow/utils/cli.py", line 114, in wrapper
    return f(*args, **kwargs)
           ^^^^^^^^^^^^^^^^^^
  File "/home/zaurall/projects/pmldl-mlops/.venv/lib/python3.11/site-packages/airflow/utils/providers_configuration_loader.py", line 55, in wrapped_function
    return func(*args, **kwargs)
           ^^^^^^^^^^^^^^^^^^^^^
  File "/home/zaurall/projects/pmldl-mlops/.venv/lib/python3.11/site-packages/airflow/cli/commands/triggerer_command.py", line 78, in triggerer
    with daemon_context, _serve_logs(args.skip_serve_logs):
  File "/home/zaurall/projects/pmldl-mlops/.venv/lib/python3.11/site-packages/daemon/daemon.py", line 365, in __enter__
    self.open()
  File "/home/zaurall/projects/pmldl-mlops/.venv/lib/python3.11/site-packages/daemon/daemon.py", line 357, in open
    self.pidfile.__enter__()
  File "/home/zaurall/projects/pmldl-mlops/.venv/lib/python3.11/site-packages/lockfile/__init__.py", line 197, in __enter__
    self.acquire()
  File "/home/zaurall/projects/pmldl-mlops/.venv/lib/python3.11/site-packages/daemon/pidfile.py", line 49, in acquire
    super().acquire(timeout, *args, **kwargs)
  File "/home/zaurall/projects/pmldl-mlops/.venv/lib/python3.11/site-packages/lockfile/pidlockfile.py", line 87, in acquire
    raise AlreadyLocked("%s is already locked" %
lockfile.AlreadyLocked: /home/zaurall/projects/pmldl-mlops/services/airflow/airflow-triggerer.pid is already locked
Traceback (most recent call last):
  File "/home/zaurall/projects/pmldl-mlops/.venv/lib/python3.11/site-packages/sqlalchemy/engine/base.py", line 1880, in _execute_context
    self.dialect.do_executemany(
  File "/home/zaurall/projects/pmldl-mlops/.venv/lib/python3.11/site-packages/sqlalchemy/engine/default.py", line 733, in do_executemany
    cursor.executemany(statement, parameters)
sqlite3.IntegrityError: UNIQUE constraint failed: job.id

The above exception was the direct cause of the following exception:

Traceback (most recent call last):
  File "/home/zaurall/projects/pmldl-mlops/.venv/bin/airflow", line 8, in <module>
    sys.exit(main())
             ^^^^^^
  File "/home/zaurall/projects/pmldl-mlops/.venv/lib/python3.11/site-packages/airflow/__main__.py", line 57, in main
    args.func(args)
  File "/home/zaurall/projects/pmldl-mlops/.venv/lib/python3.11/site-packages/airflow/cli/cli_config.py", line 49, in command
    return func(*args, **kwargs)
           ^^^^^^^^^^^^^^^^^^^^^
  File "/home/zaurall/projects/pmldl-mlops/.venv/lib/python3.11/site-packages/airflow/utils/cli.py", line 114, in wrapper
    return f(*args, **kwargs)
           ^^^^^^^^^^^^^^^^^^
  File "/home/zaurall/projects/pmldl-mlops/.venv/lib/python3.11/site-packages/airflow/utils/providers_configuration_loader.py", line 55, in wrapped_function
    return func(*args, **kwargs)
           ^^^^^^^^^^^^^^^^^^^^^
  File "/home/zaurall/projects/pmldl-mlops/.venv/lib/python3.11/site-packages/airflow/cli/commands/triggerer_command.py", line 82, in triggerer
    run_job(job=triggerer_job_runner.job, execute_callable=triggerer_job_runner._execute)
  File "/home/zaurall/projects/pmldl-mlops/.venv/lib/python3.11/site-packages/airflow/utils/session.py", line 79, in wrapper
    return func(*args, session=session, **kwargs)
           ^^^^^^^^^^^^^^^^^^^^^^^^^^^^^^^^^^^^^^
  File "/home/zaurall/projects/pmldl-mlops/.venv/lib/python3.11/site-packages/airflow/jobs/job.py", line 289, in run_job
    return execute_job(job, execute_callable=execute_callable)
           ^^^^^^^^^^^^^^^^^^^^^^^^^^^^^^^^^^^^^^^^^^^^^^^^^^^
  File "/home/zaurall/projects/pmldl-mlops/.venv/lib/python3.11/site-packages/airflow/jobs/job.py", line 318, in execute_job
    ret = execute_callable()
          ^^^^^^^^^^^^^^^^^^
  File "/home/zaurall/projects/pmldl-mlops/.venv/lib/python3.11/site-packages/airflow/jobs/triggerer_job_runner.py", line 332, in _execute
    self._run_trigger_loop()
  File "/home/zaurall/projects/pmldl-mlops/.venv/lib/python3.11/site-packages/airflow/jobs/triggerer_job_runner.py", line 360, in _run_trigger_loop
    perform_heartbeat(self.job, heartbeat_callback=self.heartbeat_callback, only_if_necessary=True)
  File "/home/zaurall/projects/pmldl-mlops/.venv/lib/python3.11/site-packages/airflow/jobs/job.py", line 350, in perform_heartbeat
    job.heartbeat(heartbeat_callback=heartbeat_callback, session=session)
  File "/home/zaurall/projects/pmldl-mlops/.venv/lib/python3.11/site-packages/airflow/utils/session.py", line 76, in wrapper
    return func(*args, **kwargs)
           ^^^^^^^^^^^^^^^^^^^^^
  File "/home/zaurall/projects/pmldl-mlops/.venv/lib/python3.11/site-packages/airflow/jobs/job.py", line 211, in heartbeat
    session.commit()
  File "/home/zaurall/projects/pmldl-mlops/.venv/lib/python3.11/site-packages/sqlalchemy/orm/session.py", line 1451, in commit
    self._transaction.commit(_to_root=self.future)
  File "/home/zaurall/projects/pmldl-mlops/.venv/lib/python3.11/site-packages/sqlalchemy/orm/session.py", line 829, in commit
    self._prepare_impl()
  File "/home/zaurall/projects/pmldl-mlops/.venv/lib/python3.11/site-packages/sqlalchemy/orm/session.py", line 808, in _prepare_impl
    self.session.flush()
  File "/home/zaurall/projects/pmldl-mlops/.venv/lib/python3.11/site-packages/sqlalchemy/orm/session.py", line 3386, in flush
    self._flush(objects)
  File "/home/zaurall/projects/pmldl-mlops/.venv/lib/python3.11/site-packages/sqlalchemy/orm/session.py", line 3525, in _flush
    with util.safe_reraise():
  File "/home/zaurall/projects/pmldl-mlops/.venv/lib/python3.11/site-packages/sqlalchemy/util/langhelpers.py", line 70, in __exit__
    compat.raise_(
  File "/home/zaurall/projects/pmldl-mlops/.venv/lib/python3.11/site-packages/sqlalchemy/util/compat.py", line 208, in raise_
    raise exception
  File "/home/zaurall/projects/pmldl-mlops/.venv/lib/python3.11/site-packages/sqlalchemy/orm/session.py", line 3486, in _flush
    flush_context.execute()
  File "/home/zaurall/projects/pmldl-mlops/.venv/lib/python3.11/site-packages/sqlalchemy/orm/unitofwork.py", line 456, in execute
    rec.execute(self)
  File "/home/zaurall/projects/pmldl-mlops/.venv/lib/python3.11/site-packages/sqlalchemy/orm/unitofwork.py", line 630, in execute
    util.preloaded.orm_persistence.save_obj(
  File "/home/zaurall/projects/pmldl-mlops/.venv/lib/python3.11/site-packages/sqlalchemy/orm/persistence.py", line 245, in save_obj
    _emit_insert_statements(
  File "/home/zaurall/projects/pmldl-mlops/.venv/lib/python3.11/site-packages/sqlalchemy/orm/persistence.py", line 1097, in _emit_insert_statements
    c = connection._execute_20(
        ^^^^^^^^^^^^^^^^^^^^^^^
  File "/home/zaurall/projects/pmldl-mlops/.venv/lib/python3.11/site-packages/sqlalchemy/engine/base.py", line 1705, in _execute_20
    return meth(self, args_10style, kwargs_10style, execution_options)
           ^^^^^^^^^^^^^^^^^^^^^^^^^^^^^^^^^^^^^^^^^^^^^^^^^^^^^^^^^^^
  File "/home/zaurall/projects/pmldl-mlops/.venv/lib/python3.11/site-packages/sqlalchemy/sql/elements.py", line 333, in _execute_on_connection
    return connection._execute_clauseelement(
           ^^^^^^^^^^^^^^^^^^^^^^^^^^^^^^^^^^
  File "/home/zaurall/projects/pmldl-mlops/.venv/lib/python3.11/site-packages/sqlalchemy/engine/base.py", line 1572, in _execute_clauseelement
    ret = self._execute_context(
          ^^^^^^^^^^^^^^^^^^^^^^
  File "/home/zaurall/projects/pmldl-mlops/.venv/lib/python3.11/site-packages/sqlalchemy/engine/base.py", line 1943, in _execute_context
    self._handle_dbapi_exception(
  File "/home/zaurall/projects/pmldl-mlops/.venv/lib/python3.11/site-packages/sqlalchemy/engine/base.py", line 2124, in _handle_dbapi_exception
    util.raise_(
  File "/home/zaurall/projects/pmldl-mlops/.venv/lib/python3.11/site-packages/sqlalchemy/util/compat.py", line 208, in raise_
    raise exception
  File "/home/zaurall/projects/pmldl-mlops/.venv/lib/python3.11/site-packages/sqlalchemy/engine/base.py", line 1880, in _execute_context
    self.dialect.do_executemany(
  File "/home/zaurall/projects/pmldl-mlops/.venv/lib/python3.11/site-packages/sqlalchemy/engine/default.py", line 733, in do_executemany
    cursor.executemany(statement, parameters)
sqlalchemy.exc.IntegrityError: (sqlite3.IntegrityError) UNIQUE constraint failed: job.id
[SQL: INSERT INTO job (id, dag_id, state, job_type, start_date, end_date, latest_heartbeat, executor_class, hostname, unixname) VALUES (?, ?, ?, ?, ?, ?, ?, ?, ?, ?)]
[parameters: ((2, None, <JobState.RUNNING: 'running'>, 'TriggererJob', '2024-09-21 20:23:33.124651', None, '2024-09-22 21:01:09.091135', None, 'DESKTOP-QAR5BLG.', 'zaurall'), (2, None, <JobState.RUNNING: 'running'>, 'TriggererJob', '2024-09-21 20:23:33.124651', None, '2024-09-22 21:01:09.091135', None, 'DESKTOP-QAR5BLG.', 'zaurall'))]
(Background on this error at: https://sqlalche.me/e/14/gkpj)
